Workbook
Name ArmourType: Helpers!$N$19
Name AttributeFilter: 'Build & Totals'!$B$2
Name BoonToggles: 'Build & Totals'!$F$57:$G$63
Name ChosenSpecs: Helpers!$A$24:$A$26
Name Class: 'Build & Totals'!$A$2
Name ConcentrationTotal: Helpers!$B$30
Name DerivedGain1: Helpers!$A$4
Name DerivedGain2: Helpers!$E$4
Name DerivedResult1: Helpers!$D$4
Name DerivedResult2: Helpers!$H$4
Name ExpertiseTotal: Helpers!$B$31
Name FlatGain: Helpers!$A$16
Name FlatResult: Helpers!$B$16
Name GearValues: 'Attributes & Prefixes'!$H$3:$S$1608
Name HealthyGain: Helpers!$A$8
Name HealthyResult: Helpers!$B$8
Name PowerSubtotal: Helpers!$A$20
Name PrecisionTotal: Helpers!$B$29
Name Rune1Bonus: Helpers!$N$3
Name Rune1Count: Helpers!$P$3
Name Rune1Stat: Helpers!$O$3
Name Rune2Bonus: Helpers!$N$4
Name Rune2Count: Helpers!$P$4
Name Rune2Stat: Helpers!$O$4
Name Rune3Bonus: Helpers!$N$5
Name Rune3Count: Helpers!$P$5
Name Rune3Stat: Helpers!$O$5
Name Rune4Bonus: Helpers!$N$6
Name Rune4Count: Helpers!$P$6
Name Rune4Stat: Helpers!$O$6
Name Rune5Bonus: Helpers!$N$7
Name Rune5Count: Helpers!$P$7
Name Rune5Stat: Helpers!$O$7
Name Rune6Bonus: Helpers!$N$8
Name Rune6Count: Helpers!$P$8
Name Rune6Stat: Helpers!$O$8
Name RuneTable: Runes!$A$2:$M$101
Name SharedGain1: Helpers!$B$12
Name SharedGain2: Helpers!$G$12
Name SharedResult1: Helpers!$E$12
Name SharedResult2: Helpers!$J$12
Name SigilTable: Sigils!$A:$B
Name Signet1: 'Build & Totals'!$A$46
Name Signet1Bonus: Helpers!$P$13
Name Signet1Check: Signets!$H$2
Name Signet1Stat: Helpers!$N$13
Name Signet2: 'Build & Totals'!$A$47
Name Signet2Bonus: Helpers!$P$14
Name Signet2Check: Signets!$H$3
Name Signet2Stat: Helpers!$N$14
Name Signet3: 'Build & Totals'!$A$48
Name Signet3Bonus: Helpers!$P$15
Name Signet3Check: Signets!$H$4
Name Signet3Stat: Helpers!$N$15
Name SignetPassives: Signets!$A$1:$D$16
Name SignetTable: Signets!$A$18:$D$61
Name Spec1: 'Build & Totals'!$B$4
Name Spec1MajorAdept: 'Build & Totals'!$B$5
Name Spec1MajorAdeptCondition: 'Trait Selection'!$C$4
Name Spec1MajorAdeptStacking: 'Trait Filters & Checks'!$E$19

Sheet Build & Totals
A1: Character Class | B1: Attribute Filter | C1: Attributes
A2: Engineer | B2: (Select)
A3: Specialisations & Traits | C3: Power | D3: Precision | E3: Toughness | F3: Vitality | G3: Concentration | H3: Condition Damage | I3: Expertise | J3: Ferocity | K3: Healing Power | L3: Defence
A4: Specialisation 1 | B4: Illusions | C4: {=_xlfn.LET(_xlpm.amount,'Conditionals Helper'!P128,IF(_xlpm.amount=0,"",_xlpm.amount))} | D4: {=_xlfn.LET(_xlpm.amount,'Conditionals Helper'!Q128,IF(_xlpm.amount=0,"",_xlpm.amount))} | E4: {=_xlfn.LET(_xlpm.amount,'Conditionals Helper'!R128,IF(_xlpm.amount=0,"",_xlpm.amount))} | F4: {=_xlfn.LET(_xlpm.amount,'Conditionals Helper'!S128,IF(_xlpm.amount=0,"",_xlpm.amount))} | G4: {=_xlfn.LET(_xlpm.amount,'Conditionals Helper'!T128,IF(_xlpm.amount=0,"",_xlpm.amount))} | H4: {=_xlfn.LET(_xlpm.amount,'Conditionals Helper'!U128,IF(_xlpm.amount=0,"",_xlpm.amount))} -> 9.6 | I4: {=_xlfn.LET(_xlpm.amount,'Conditionals Helper'!V128,IF(_xlpm.amount=0,"",_xlpm.amount))} | J4: {=_xlfn.LET(_xlpm.amount,'Conditionals Helper'!W128,IF(_xlpm.amount=0,"",_xlpm.amount))} | K4: {=_xlfn.LET(_xlpm.amount,'Conditionals Helper'!X128,IF(_xlpm.amount=0,"",_xlpm.amount))} | N4: Legend
A5: Major Adept | B5: Persistence of Memory | C5: {=_xlfn.LET(_xlpm.amount,'Conditionals Helper'!P$14,IF(_xlpm.amount=0,"",_xlpm.amount))} | D5: {=_xlfn.LET(_xlpm.amount,'Conditionals Helper'!Q$14,IF(_xlpm.amount=0,"",_xlpm.amount))} | E5: {=_xlfn.LET(_xlpm.amount,'Conditionals Helper'!R$14,IF(_xlpm.amount=0,"",_xlpm.amount))} | F5: {=_xlfn.LET(_xlpm.amount,'Conditionals Helper'!S$14,IF(_xlpm.amount=0,"",_xlpm.amount))} | G5: {=_xlfn.LET(_xlpm.amount,'Conditionals Helper'!T$14,IF(_xlpm.amount=0,"",_xlpm.amount))} | H5: {=_xlfn.LET(_xlpm.amount,'Conditionals Helper'!U$14,IF(_xlpm.amount=0,"",_xlpm.amount))} | I5: {=_xlfn.LET(_xlpm.amount,'Conditionals Helper'!V$14,IF(_xlpm.amount=0,"",_xlpm.amount))} | J5: {=_xlfn.LET(_xlpm.amount,'Conditionals Helper'!W$14,IF(_xlpm.amount=0,"",_xlpm.amount))} | K5: {=_xlfn.LET(_xlpm.amount,'Conditionals Helper'!X$14,IF(_xlpm.amount=0,"",_xlpm.amount))} | N5: Section Bar
A6: Major Master | B6: (Select) | C6: {=_xlfn.LET(_xlpm.amount,'Conditionals Helper'!P$28,IF(_xlpm.amount=0,"",_xlpm.amount))} | D6: {=_xlfn.LET(_xlpm.amount,'Conditionals Helper'!Q$28,IF(_xlpm.amount=0,"",_xlpm.amount))} | E6: {=_xlfn.LET(_xlpm.amount,'Conditionals Helper'!R$28,IF(_xlpm.amount=0,"",_xlpm.amount))} | F6: {=_xlfn.LET(_xlpm.amount,'Conditionals Helper'!S$28,IF(_xlpm.amount=0,"",_xlpm.amount))} | G6: {=_xlfn.LET(_xlpm.amount,'Conditionals Helper'!T$28,IF(_xlpm.amount=0,"",_xlpm.amount))} | H6: {=_xlfn.LET(_xlpm.amount,'Conditionals Helper'!U$28,IF(_xlpm.amount=0,"",_xlpm.amount))} | I6: {=_xlfn.LET(_xlpm.amount,'Conditionals Helper'!V$28,IF(_xlpm.amount=0,"",_xlpm.amount))} | J6: {=_xlfn.LET(_xlpm.amount,'Conditionals Helper'!W$28,IF(_xlpm.amount=0,"",_xlpm.amount))} | K6: {=_xlfn.LET(_xlpm.amount,'Conditionals Helper'!X$28,IF(_xlpm.amount=0,"",_xlpm.amount))} | N6: Subsection
A7: Major Grandmaster | B7: (Select) | C7: {=_xlfn.LET(_xlpm.amount,'Conditionals Helper'!P$42,IF(_xlpm.amount=0,"",_xlpm.amount))} | D7: {=_xlfn.LET(_xlpm.amount,'Conditionals Helper'!Q$42,IF(_xlpm.amount=0,"",_xlpm.amount))} | E7: {=_xlfn.LET(_xlpm.amount,'Conditionals Helper'!R$42,IF(_xlpm.amount=0,"",_xlpm.amount))} | F7: {=_xlfn.LET(_xlpm.amount,'Conditionals Helper'!S$42,IF(_xlpm.amount=0,"",_xlpm.amount))} | G7: {=_xlfn.LET(_xlpm.amount,'Conditionals Helper'!T$42,IF(_xlpm.amount=0,"",_xlpm.amount))} | H7: {=_xlfn.LET(_xlpm.amount,'Conditionals Helper'!U$42,IF(_xlpm.amount=0,"",_xlpm.amount))} | I7: {=_xlfn.LET(_xlpm.amount,'Conditionals Helper'!V$42,IF(_xlpm.amount=0,"",_xlpm.amount))} | J7: {=_xlfn.LET(_xlpm.amount,'Conditionals Helper'!W$42,IF(_xlpm.amount=0,"",_xlpm.amount))} | K7: {=_xlfn.LET(_xlpm.amount,'Conditionals Helper'!X$42,IF(_xlpm.amount=0,"",_xlpm.amount))} | N7: Category
A8: Specialisation 2 | B8: Inspiration | C8: {=_xlfn.LET(_xlpm.amount,'Conditionals Helper'!P129,IF(_xlpm.amount=0,"",_xlpm.amount))} | D8: {=_xlfn.LET(_xlpm.amount,'Conditionals Helper'!Q129,IF(_xlpm.amount=0,"",_xlpm.amount))} | E8: {=_xlfn.LET(_xlpm.amount,'Conditionals Helper'!R129,IF(_xlpm.amount=0,"",_xlpm.amount))} | F8: {=_xlfn.LET(_xlpm.amount,'Conditionals Helper'!S129,IF(_xlpm.amount=0,"",_xlpm.amount))} | G8: {=_xlfn.LET(_xlpm.amount,'Conditionals Helper'!T129,IF(_xlpm.amount=0,"",_xlpm.amount))} | H8: {=_xlfn.LET(_xlpm.amount,'Conditionals Helper'!U129,IF(_xlpm.amount=0,"",_xlpm.amount))} | I8: {=_xlfn.LET(_xlpm.amount,'Conditionals Helper'!V129,IF(_xlpm.amount=0,"",_xlpm.amount))} | J8: {=_xlfn.LET(_xlpm.amount,'Conditionals Helper'!W129,IF(_xlpm.amount=0,"",_xlpm.amount))} | K8: {=_xlfn.LET(_xlpm.amount,'Conditionals Helper'!X129,IF(_xlpm.amount=0,"",_xlpm.amount))} | N8: Input
A9: Major Adept | B9: (Select) | C9: {=_xlfn.LET(_xlpm.amount,'Conditionals Helper'!P$56,IF(_xlpm.amount=0,"",_xlpm.amount))} | D9: {=_xlfn.LET(_xlpm.amount,'Conditionals Helper'!Q$56,IF(_xlpm.amount=0,"",_xlpm.amount))} | E9: {=_xlfn.LET(_xlpm.amount,'Conditionals Helper'!R$56,IF(_xlpm.amount=0,"",_xlpm.amount))} | F9: {=_xlfn.LET(_xlpm.amount,'Conditionals Helper'!S$56,IF(_xlpm.amount=0,"",_xlpm.amount))} | G9: {=_xlfn.LET(_xlpm.amount,'Conditionals Helper'!T$56,IF(_xlpm.amount=0,"",_xlpm.amount))} | H9: {=_xlfn.LET(_xlpm.amount,'Conditionals Helper'!U$56,IF(_xlpm.amount=0,"",_xlpm.amount))} | I9: {=_xlfn.LET(_xlpm.amount,'Conditionals Helper'!V$56,IF(_xlpm.amount=0,"",_xlpm.amount))} | J9: {=_xlfn.LET(_xlpm.amount,'Conditionals Helper'!W$56,IF(_xlpm.amount=0,"",_xlpm.amount))} | K9: {=_xlfn.LET(_xlpm.amount,'Conditionals Helper'!X$56,IF(_xlpm.amount=0,"",_xlpm.amount))} | N9: Major Stat/Celestial
A10: Major Master | B10: Warden's Feedback | C10: {=_xlfn.LET(_xlpm.amount,'Conditionals Helper'!P$70,IF(_xlpm.amount=0,"",_xlpm.amount))} | D10: {=_xlfn.LET(_xlpm.amount,'Conditionals Helper'!Q$70,IF(_xlpm.amount=0,"",_xlpm.amount))} | E10: {=_xlfn.LET(_xlpm.amount,'Conditionals Helper'!R$70,IF(_xlpm.amount=0,"",_xlpm.amount))} | F10: {=_xlfn.LET(_xlpm.amount,'Conditionals Helper'!S$70,IF(_xlpm.amount=0,"",_xlpm.amount))} | G10: {=_xlfn.LET(_xlpm.amount,'Conditionals Helper'!T$70,IF(_xlpm.amount=0,"",_xlpm.amount))} | H10: {=_xlfn.LET(_xlpm.amount,'Conditionals Helper'!U$70,IF(_xlpm.amount=0,"",_xlpm.amount))} | I10: {=_xlfn.LET(_xlpm.amount,'Conditionals Helper'!V$70,IF(_xlpm.amount=0,"",_xlpm.amount))} | J10: {=_xlfn.LET(_xlpm.amount,'Conditionals Helper'!W$70,IF(_xlpm.amount=0,"",_xlpm.amount))} | K10: {=_xlfn.LET(_xlpm.amount,'Conditionals Helper'!X$70,IF(_xlpm.amount=0,"",_xlpm.amount))} | N10: Minor Stat
A11: Major Grandmaster | B11: (Select) | C11: {=_xlfn.LET(_xlpm.amount,'Conditionals Helper'!P$84,IF(_xlpm.amount=0,"",_xlpm.amount))} | D11: {=_xlfn.LET(_xlpm.amount,'Conditionals Helper'!Q$84,IF(_xlpm.amount=0,"",_xlpm.amount))} | E11: {=_xlfn.LET(_xlpm.amount,'Conditionals Helper'!R$84,IF(_xlpm.amount=0,"",_xlpm.amount))} | F11: {=_xlfn.LET(_xlpm.amount,'Conditionals Helper'!S$84,IF(_xlpm.amount=0,"",_xlpm.amount))} | G11: {=_xlfn.LET(_xlpm.amount,'Conditionals Helper'!T$84,IF(_xlpm.amount=0,"",_xlpm.amount))} | H11: {=_xlfn.LET(_xlpm.amount,'Conditionals Helper'!U$84,IF(_xlpm.amount=0,"",_xlpm.amount))} | I11: {=_xlfn.LET(_xlpm.amount,'Conditionals Helper'!V$84,IF(_xlpm.amount=0,"",_xlpm.amount))} | J11: {=_xlfn.LET(_xlpm.amount,'Conditionals Helper'!W$84,IF(_xlpm.amount=0,"",_xlpm.amount))} | K11: {=_xlfn.LET(_xlpm.amount,'Conditionals Helper'!X$84,IF(_xlpm.amount=0,"",_xlpm.amount))} | N11: Incompatible
A12: Specialisation 3 | B12: Troubadour | C12: {=_xlfn.LET(_xlpm.amount,'Conditionals Helper'!P130,IF(_xlpm.amount=0,"",_xlpm.amount))} | D12: {=_xlfn.LET(_xlpm.amount,'Conditionals Helper'!Q130,IF(_xlpm.amount=0,"",_xlpm.amount))} | E12: {=_xlfn.LET(_xlpm.amount,'Conditionals Helper'!R130,IF(_xlpm.amount=0,"",_xlpm.amount))} | F12: {=_xlfn.LET(_xlpm.amount,'Conditionals Helper'!S130,IF(_xlpm.amount=0,"",_xlpm.amount))} | G12: {=_xlfn.LET(_xlpm.amount,'Conditionals Helper'!T130,IF(_xlpm.amount=0,"",_xlpm.amount))} | H12: {=_xlfn.LET(_xlpm.amount,'Conditionals Helper'!U130,IF(_xlpm.amount=0,"",_xlpm.amount))} -> 62.4 | I12: {=_xlfn.LET(_xlpm.amount,'Conditionals Helper'!V130,IF(_xlpm.amount=0,"",_xlpm.amount))} | J12: {=_xlfn.LET(_xlpm.amount,'Conditionals Helper'!W130,IF(_xlpm.amount=0,"",_xlpm.amount))} | K12: {=_xlfn.LET(_xlpm.amount,'Conditionals Helper'!X130,IF(_xlpm.amount=0,"",_xlpm.amount))}
A13: Major Adept | B13: Illusionary Defense | C13: {=_xlfn.LET(_xlpm.amount,'Conditionals Helper'!P$98,IF(_xlpm.amount=0,"",_xlpm.amount))} | D13: {=_xlfn.LET(_xlpm.amount,'Conditionals Helper'!Q$98,IF(_xlpm.amount=0,"",_xlpm.amount))} | E13: {=_xlfn.LET(_xlpm.amount,'Conditionals Helper'!R$98,IF(_xlpm.amount=0,"",_xlpm.amount))} | F13: {=_xlfn.LET(_xlpm.amount,'Conditionals Helper'!S$98,IF(_xlpm.amount=0,"",_xlpm.amount))} | G13: {=_xlfn.LET(_xlpm.amount,'Conditionals Helper'!T$98,IF(_xlpm.amount=0,"",_xlpm.amount))} | H13: {=_xlfn.LET(_xlpm.amount,'Conditionals Helper'!U$98,IF(_xlpm.amount=0,"",_xlpm.amount))} | I13: {=_xlfn.LET(_xlpm.amount,'Conditionals Helper'!V$98,IF(_xlpm.amount=0,"",_xlpm.amount))} | J13: {=_xlfn.LET(_xlpm.amount,'Conditionals Helper'!W$98,IF(_xlpm.amount=0,"",_xlpm.amount))} | K13: {=_xlfn.LET(_xlpm.amount,'Conditionals Helper'!X$98,IF(_xlpm.amount=0,"",_xlpm.amount))}
A14: Major Master | B14: (Select) | C14: {=_xlfn.LET(_xlpm.amount,'Conditionals Helper'!P$112,IF(_xlpm.amount=0,"",_xlpm.amount))} | D14: {=_xlfn.LET(_xlpm.amount,'Conditionals Helper'!Q$112,IF(_xlpm.amount=0,"",_xlpm.amount))} | E14: {=_xlfn.LET(_xlpm.amount,'Conditionals Helper'!R$112,IF(_xlpm.amount=0,"",_xlpm.amount))} | F14: {=_xlfn.LET(_xlpm.amount,'Conditionals Helper'!S$112,IF(_xlpm.amount=0,"",_xlpm.amount))} | G14: {=_xlfn.LET(_xlpm.amount,'Conditionals Helper'!T$112,IF(_xlpm.amount=0,"",_xlpm.amount))} | H14: {=_xlfn.LET(_xlpm.amount,'Conditionals Helper'!U$112,IF(_xlpm.amount=0,"",_xlpm.amount))} | I14: {=_xlfn.LET(_xlpm.amount,'Conditionals Helper'!V$112,IF(_xlpm.amount=0,"",_xlpm.amount))} | J14: {=_xlfn.LET(_xlpm.amount,'Conditionals Helper'!W$112,IF(_xlpm.amount=0,"",_xlpm.amount))} | K14: {=_xlfn.LET(_xlpm.amount,'Conditionals Helper'!X$112,IF(_xlpm.amount=0,"",_xlpm.amount))}
A15: Major Grandmaster | B15: (Select) | C15: {=_xlfn.LET(_xlpm.amount,'Conditionals Helper'!P$126,IF(_xlpm.amount=0,"",_xlpm.amount))} | D15: {=_xlfn.LET(_xlpm.amount,'Conditionals Helper'!Q$126,IF(_xlpm.amount=0,"",_xlpm.amount))} | E15: {=_xlfn.LET(_xlpm.amount,'Conditionals Helper'!R$126,IF(_xlpm.amount=0,"",_xlpm.amount))} | F15: {=_xlfn.LET(_xlpm.amount,'Conditionals Helper'!S$126,IF(_xlpm.amount=0,"",_xlpm.amount))} | G15: {=_xlfn.LET(_xlpm.amount,'Conditionals Helper'!T$126,IF(_xlpm.amount=0,"",_xlpm.amount))} | H15: {=_xlfn.LET(_xlpm.amount,'Conditionals Helper'!U$126,IF(_xlpm.amount=0,"",_xlpm.amount))} | I15: {=_xlfn.LET(_xlpm.amount,'Conditionals Helper'!V$126,IF(_xlpm.amount=0,"",_xlpm.amount))} | J15: {=_xlfn.LET(_xlpm.amount,'Conditionals Helper'!W$126,IF(_xlpm.amount=0,"",_xlpm.amount))} | K15: {=_xlfn.LET(_xlpm.amount,'Conditionals Helper'!X$126,IF(_xlpm.amount=0,"",_xlpm.amount))}
A16: Gear | C16: Power | D16: Precision | E16: Toughness | F16: Vitality | G16: Concentration | H16: Condition Damage | I16: Expertise | J16: Ferocity | K16: Healing Power | L16: Defence
A17: Weapon (1H) | B17: Assassin | C17: =IF(AND(COUNTBLANK($B17)=0,NOT($B17="(Select)")), VLOOKUP(_xlfn.CONCAT($B17, $A17), GearValues, 4, 0), " ") -> 85 | D17: =IF(AND(COUNTBLANK($B17)=0,NOT($B17="(Select)")), VLOOKUP(_xlfn.CONCAT($B17, $A17), GearValues, 5, 0), " ") -> 120 | E17: =IF(AND(COUNTBLANK($B17)=0,NOT($B17="(Select)")), VLOOKUP(_xlfn.CONCAT($B17, $A17), GearValues, 6, 0), " ") | F17: =IF(AND(COUNTBLANK($B17)=0,NOT($B17="(Select)")), VLOOKUP(_xlfn.CONCAT($B17, $A17), GearValues, 7, 0), " ") | G17: =IF(AND(COUNTBLANK($B17)=0,NOT($B17="(Select)")), VLOOKUP(_xlfn.CONCAT($B17, $A17), GearValues, 8, 0), " ") | H17: =IF(AND(COUNTBLANK($B17)=0,NOT($B17="(Select)")), VLOOKUP(_xlfn.CONCAT($B17, $A17), GearValues, 9, 0), " ") | I17: =IF(AND(COUNTBLANK($B17)=0,NOT($B17="(Select)")), VLOOKUP(_xlfn.CONCAT($B17, $A17), GearValues, 10, 0), " ") | J17: =IF(AND(COUNTBLANK($B17)=0,NOT($B17="(Select)")), VLOOKUP(_xlfn.CONCAT($B17, $A17), GearValues, 11, 0), " ") -> 85 | K17: =IF(AND(COUNTBLANK($B17)=0,NOT($B17="(Select)")), VLOOKUP(_xlfn.CONCAT($B17, $A17), GearValues, 12, 0), " ")
A18: Weapon (1H) | B18: Assassin | C18: =IF(AND(COUNTBLANK($B18)=0,NOT($B18="(Select)")), VLOOKUP(_xlfn.CONCAT($B18, $A18), GearValues, 4, 0), " ") -> 85 | D18: =IF(AND(COUNTBLANK($B18)=0,NOT($B18="(Select)")), VLOOKUP(_xlfn.CONCAT($B18, $A18), GearValues, 5, 0), " ") -> 120 | E18: =IF(AND(COUNTBLANK($B18)=0,NOT($B18="(Select)")), VLOOKUP(_xlfn.CONCAT($B18, $A18), GearValues, 6, 0), " ") | F18: =IF(AND(COUNTBLANK($B18)=0,NOT($B18="(Select)")), VLOOKUP(_xlfn.CONCAT($B18, $A18), GearValues, 7, 0), " ") | G18: =IF(AND(COUNTBLANK($B18)=0,NOT($B18="(Select)")), VLOOKUP(_xlfn.CONCAT($B18, $A18), GearValues, 8, 0), " ") | H18: =IF(AND(COUNTBLANK($B18)=0,NOT($B18="(Select)")), VLOOKUP(_xlfn.CONCAT($B18, $A18), GearValues, 9, 0), " ") | I18: =IF(AND(COUNTBLANK($B18)=0,NOT($B18="(Select)")), VLOOKUP(_xlfn.CONCAT($B18, $A18), GearValues, 10, 0), " ") | J18: =IF(AND(COUNTBLANK($B18)=0,NOT($B18="(Select)")), VLOOKUP(_xlfn.CONCAT($B18, $A18), GearValues, 11, 0), " ") -> 85 | K18: =IF(AND(COUNTBLANK($B18)=0,NOT($B18="(Select)")), VLOOKUP(_xlfn.CONCAT($B18, $A18), GearValues, 12, 0), " ")
A19: Weapon (2H) | B19: (Select) | C19: =IF(AND(COUNTBLANK($B19)=0,NOT($B19="(Select)")), VLOOKUP(_xlfn.CONCAT($B19, $A19), GearValues, 4, 0), " ") | D19: =IF(AND(COUNTBLANK($B19)=0,NOT($B19="(Select)")), VLOOKUP(_xlfn.CONCAT($B19, $A19), GearValues, 5, 0), " ") | E19: =IF(AND(COUNTBLANK($B19)=0,NOT($B19="(Select)")), VLOOKUP(_xlfn.CONCAT($B19, $A19), GearValues, 6, 0), " ") | F19: =IF(AND(COUNTBLANK($B19)=0,NOT($B19="(Select)")), VLOOKUP(_xlfn.CONCAT($B19, $A19), GearValues, 7, 0), " ") | G19: =IF(AND(COUNTBLANK($B19)=0,NOT($B19="(Select)")), VLOOKUP(_xlfn.CONCAT($B19, $A19), GearValues, 8, 0), " ") | H19: =IF(AND(COUNTBLANK($B19)=0,NOT($B19="(Select)")), VLOOKUP(_xlfn.CONCAT($B19, $A19), GearValues, 9, 0), " ") | I19: =IF(AND(COUNTBLANK($B19)=0,NOT($B19="(Select)")), VLOOKUP(_xlfn.CONCAT($B19, $A19), GearValues, 10, 0), " ") | J19: =IF(AND(COUNTBLANK($B19)=0,NOT($B19="(Select)")), VLOOKUP(_xlfn.CONCAT($B19, $A19), GearValues, 11, 0), " ") | K19: =IF(AND(COUNTBLANK($B19)=0,NOT($B19="(Select)")), VLOOKUP(_xlfn.CONCAT($B19, $A19), GearValues, 12, 0), " ")
A20: Head | B20: Captain | C20: =IF(AND(COUNTBLANK($B20)=0,NOT($B20="(Select)")), VLOOKUP(_xlfn.CONCAT($B20, $A20), GearValues, 4, 0), " ") -> 43 | D20: =IF(AND(COUNTBLANK($B20)=0,NOT($B20="(Select)")), VLOOKUP(_xlfn.CONCAT($B20, $A20), GearValues, 5, 0), " ") -> 60 | E20: =IF(AND(COUNTBLANK($B20)=0,NOT($B20="(Select)")), VLOOKUP(_xlfn.CONCAT($B20, $A20), GearValues, 6, 0), " ") -> 43 | F20: =IF(AND(COUNTBLANK($B20)=0,NOT($B20="(Select)")), VLOOKUP(_xlfn.CONCAT($B20, $A20), GearValues, 7, 0), " ") | G20: =IF(AND(COUNTBLANK($B20)=0,NOT($B20="(Select)")), VLOOKUP(_xlfn.CONCAT($B20, $A20), GearValues, 8, 0), " ") | H20: =IF(AND(COUNTBLANK($B20)=0,NOT($B20="(Select)")), VLOOKUP(_xlfn.CONCAT($B20, $A20), GearValues, 9, 0), " ") | I20: =IF(AND(COUNTBLANK($B20)=0,NOT($B20="(Select)")), VLOOKUP(_xlfn.CONCAT($B20, $A20), GearValues, 10, 0), " ") | J20: =IF(AND(COUNTBLANK($B20)=0,NOT($B20="(Select)")), VLOOKUP(_xlfn.CONCAT($B20, $A20), GearValues, 11, 0), " ") | K20: =IF(AND(COUNTBLANK($B20)=0,NOT($B20="(Select)")), VLOOKUP(_xlfn.CONCAT($B20, $A20), GearValues, 12, 0), " ") | L20: =IF(AND(COUNTBLANK($B20)=0,NOT($B20="(Select)")),VLOOKUP($A20,'Gear Values'!$A$17:$D$23,MATCH(ArmourType,'Gear Values'!$A$16:$D$16,0),0),"") -> 97
A21: Shoulders | B21: Apostate | C21: =IF(AND(COUNTBLANK($B21)=0,NOT($B21="(Select)")), VLOOKUP(_xlfn.CONCAT($B21, $A21), GearValues, 4, 0), " ") | D21: =IF(AND(COUNTBLANK($B21)=0,NOT($B21="(Select)")), VLOOKUP(_xlfn.CONCAT($B21, $A21), GearValues, 5, 0), " ") | E21: =IF(AND(COUNTBLANK($B21)=0,NOT($B21="(Select)")), VLOOKUP(_xlfn.CONCAT($B21, $A21), GearValues, 6, 0), " ") -> 32 | F21: =IF(AND(COUNTBLANK($B21)=0,NOT($B21="(Select)")), VLOOKUP(_xlfn.CONCAT($B21, $A21), GearValues, 7, 0), " ") | G21: =IF(AND(COUNTBLANK($B21)=0,NOT($B21="(Select)")), VLOOKUP(_xlfn.CONCAT($B21, $A21), GearValues, 8, 0), " ") | H21: =IF(AND(COUNTBLANK($B21)=0,NOT($B21="(Select)")), VLOOKUP(_xlfn.CONCAT($B21, $A21), GearValues, 9, 0), " ") -> 45 | I21: =IF(AND(COUNTBLANK($B21)=0,NOT($B21="(Select)")), VLOOKUP(_xlfn.CONCAT($B21, $A21), GearValues, 10, 0), " ") | J21: =IF(AND(COUNTBLANK($B21)=0,NOT($B21="(Select)")), VLOOKUP(_xlfn.CONCAT($B21, $A21), GearValues, 11, 0), " ") | K21: =IF(AND(COUNTBLANK($B21)=0,NOT($B21="(Select)")), VLOOKUP(_xlfn.CONCAT($B21, $A21), GearValues, 12, 0), " ") -> 32 | L21: =IF(AND(COUNTBLANK($B21)=0,NOT($B21="(Select)")),VLOOKUP($A21,'Gear Values'!$A$17:$D$23,MATCH(ArmourType,'Gear Values'!$A$16:$D$16,0),0),"") -> 97
A22: Chest | B22: Captain | C22: =IF(AND(COUNTBLANK($B22)=0,NOT($B22="(Select)")), VLOOKUP(_xlfn.CONCAT($B22, $A22), GearValues, 4, 0), " ") -> 96 | D22: =IF(AND(COUNTBLANK($B22)=0,NOT($B22="(Select)")), VLOOKUP(_xlfn.CONCAT($B22, $A22), GearValues, 5, 0), " ") -> 134 | E22: =IF(AND(COUNTBLANK($B22)=0,NOT($B22="(Select)")), VLOOKUP(_xlfn.CONCAT($B22, $A22), GearValues, 6, 0), " ") -> 96 | F22: =IF(AND(COUNTBLANK($B22)=0,NOT($B22="(Select)")), VLOOKUP(_xlfn.CONCAT($B22, $A22), GearValues, 7, 0), " ") | G22: =IF(AND(COUNTBLANK($B22)=0,NOT($B22="(Select)")), VLOOKUP(_xlfn.CONCAT($B22, $A22), GearValues, 8, 0), " ") | H22: =IF(AND(COUNTBLANK($B22)=0,NOT($B22="(Select)")), VLOOKUP(_xlfn.CONCAT($B22, $A22), GearValues, 9, 0), " ") | I22: =IF(AND(COUNTBLANK($B22)=0,NOT($B22="(Select)")), VLOOKUP(_xlfn.CONCAT($B22, $A22), GearValues, 10, 0), " ") | J22: =IF(AND(COUNTBLANK($B22)=0,NOT($B22="(Select)")), VLOOKUP(_xlfn.CONCAT($B22, $A22), GearValues, 11, 0), " ") | K22: =IF(AND(COUNTBLANK($B22)=0,NOT($B22="(Select)")), VLOOKUP(_xlfn.CONCAT($B22, $A22), GearValues, 12, 0), " ") | L22: =IF(AND(COUNTBLANK($B22)=0,NOT($B22="(Select)")),VLOOKUP($A22,'Gear Values'!$A$17:$D$23,MATCH(ArmourType,'Gear Values'!$A$16:$D$16,0),0),"") -> 338
A23: Hands | B23: Marauder | C23: =IF(AND(COUNTBLANK($B23)=0,NOT($B23="(Select)")), VLOOKUP(_xlfn.CONCAT($B23, $A23), GearValues, 4, 0), " ") -> 38 | D23: =IF(AND(COUNTBLANK($B23)=0,NOT($B23="(Select)")), VLOOKUP(_xlfn.CONCAT($B23, $A23), GearValues, 5, 0), " ") -> 38 | E23: =IF(AND(COUNTBLANK($B23)=0,NOT($B23="(Select)")), VLOOKUP(_xlfn.CONCAT($B23, $A23), GearValues, 6, 0), " ") | F23: =IF(AND(COUNTBLANK($B23)=0,NOT($B23="(Select)")), VLOOKUP(_xlfn.CONCAT($B23, $A23), GearValues, 7, 0), " ") -> 21 | G23: =IF(AND(COUNTBLANK($B23)=0,NOT($B23="(Select)")), VLOOKUP(_xlfn.CONCAT($B23, $A23), GearValues, 8, 0), " ") | H23: =IF(AND(COUNTBLANK($B23)=0,NOT($B23="(Select)")), VLOOKUP(_xlfn.CONCAT($B23, $A23), GearValues, 9, 0), " ") | I23: =IF(AND(COUNTBLANK($B23)=0,NOT($B23="(Select)")), VLOOKUP(_xlfn.CONCAT($B23, $A23), GearValues, 10, 0), " ") | J23: =IF(AND(COUNTBLANK($B23)=0,NOT($B23="(Select)")), VLOOKUP(_xlfn.CONCAT($B23, $A23), GearValues, 11, 0), " ") -> 21 | K23: =IF(AND(COUNTBLANK($B23)=0,NOT($B23="(Select)")), VLOOKUP(_xlfn.CONCAT($B23, $A23), GearValues, 12, 0), " ") | L23: =IF(AND(COUNTBLANK($B23)=0,NOT($B23="(Select)")),VLOOKUP($A23,'Gear Values'!$A$17:$D$23,MATCH(ArmourType,'Gear Values'!$A$16:$D$16,0),0),"") -> 157
A24: Legs | B24: Marauder | C24: =IF(AND(COUNTBLANK($B24)=0,NOT($B24="(Select)")), VLOOKUP(_xlfn.CONCAT($B24, $A24), GearValues, 4, 0), " ") -> 77 | D24: =IF(AND(COUNTBLANK($B24)=0,NOT($B24="(Select)")), VLOOKUP(_xlfn.CONCAT($B24, $A24), GearValues, 5, 0), " ") -> 77 | E24: =IF(AND(COUNTBLANK($B24)=0,NOT($B24="(Select)")), VLOOKUP(_xlfn.CONCAT($B24, $A24), GearValues, 6, 0), " ") | F24: =IF(AND(COUNTBLANK($B24)=0,NOT($B24="(Select)")), VLOOKUP(_xlfn.CONCAT($B24, $A24), GearValues, 7, 0), " ") -> 42 | G24: =IF(AND(COUNTBLANK($B24)=0,NOT($B24="(Select)")), VLOOKUP(_xlfn.CONCAT($B24, $A24), GearValues, 8, 0), " ") | H24: =IF(AND(COUNTBLANK($B24)=0,NOT($B24="(Select)")), VLOOKUP(_xlfn.CONCAT($B24, $A24), GearValues, 9, 0), " ") | I24: =IF(AND(COUNTBLANK($B24)=0,NOT($B24="(Select)")), VLOOKUP(_xlfn.CONCAT($B24, $A24), GearValues, 10, 0), " ") | J24: =IF(AND(COUNTBLANK($B24)=0,NOT($B24="(Select)")), VLOOKUP(_xlfn.CONCAT($B24, $A24), GearValues, 11, 0), " ") -> 42 | K24: =IF(AND(COUNTBLANK($B24)=0,NOT($B24="(Select)")), VLOOKUP(_xlfn.CONCAT($B24, $A24), GearValues, 12, 0), " ") | L24: =IF(AND(COUNTBLANK($B24)=0,NOT($B24="(Select)")),VLOOKUP($A24,'Gear Values'!$A$17:$D$23,MATCH(ArmourType,'Gear Values'!$A$16:$D$16,0),0),"") -> 218
A25: Feet | B25: (Select) | C25: =IF(AND(COUNTBLANK($B25)=0,NOT($B25="(Select)")), VLOOKUP(_xlfn.CONCAT($B25, $A25), GearValues, 4, 0), " ") | D25: =IF(AND(COUNTBLANK($B25)=0,NOT($B25="(Select)")), VLOOKUP(_xlfn.CONCAT($B25, $A25), GearValues, 5, 0), " ") | E25: =IF(AND(COUNTBLANK($B25)=0,NOT($B25="(Select)")), VLOOKUP(_xlfn.CONCAT($B25, $A25), GearValues, 6, 0), " ") | F25: =IF(AND(COUNTBLANK($B25)=0,NOT($B25="(Select)")), VLOOKUP(_xlfn.CONCAT($B25, $A25), GearValues, 7, 0), " ") | G25: =IF(AND(COUNTBLANK($B25)=0,NOT($B25="(Select)")), VLOOKUP(_xlfn.CONCAT($B25, $A25), GearValues, 8, 0), " ") | H25: =IF(AND(COUNTBLANK($B25)=0,NOT($B25="(Select)")), VLOOKUP(_xlfn.CONCAT($B25, $A25), GearValues, 9, 0), " ") | I25: =IF(AND(COUNTBLANK($B25)=0,NOT($B25="(Select)")), VLOOKUP(_xlfn.CONCAT($B25, $A25), GearValues, 10, 0), " ") | J25: =IF(AND(COUNTBLANK($B25)=0,NOT($B25="(Select)")), VLOOKUP(_xlfn.CONCAT($B25, $A25), GearValues, 11, 0), " ") | K25: =IF(AND(COUNTBLANK($B25)=0,NOT($B25="(Select)")), VLOOKUP(_xlfn.CONCAT($B25, $A25), GearValues, 12, 0), " ") | L25: =IF(AND(COUNTBLANK($B25)=0,NOT($B25="(Select)")),VLOOKUP($A25,'Gear Values'!$A$17:$D$23,MATCH(ArmourType,'Gear Values'!$A$16:$D$16,0),0),"")
A26: Ear | B26: (Select) | C26: =IF(AND(COUNTBLANK($B26)=0,NOT($B26="(Select)")), VLOOKUP(_xlfn.CONCAT($B26, $A26), GearValues, 4, 0), " ") | D26: =IF(AND(COUNTBLANK($B26)=0,NOT($B26="(Select)")), VLOOKUP(_xlfn.CONCAT($B26, $A26), GearValues, 5, 0), " ") | E26: =IF(AND(COUNTBLANK($B26)=0,NOT($B26="(Select)")), VLOOKUP(_xlfn.CONCAT($B26, $A26), GearValues, 6, 0), " ") | F26: =IF(AND(COUNTBLANK($B26)=0,NOT($B26="(Select)")), VLOOKUP(_xlfn.CONCAT($B26, $A26), GearValues, 7, 0), " ") | G26: =IF(AND(COUNTBLANK($B26)=0,NOT($B26="(Select)")), VLOOKUP(_xlfn.CONCAT($B26, $A26), GearValues, 8, 0), " ") | H26: =IF(AND(COUNTBLANK($B26)=0,NOT($B26="(Select)")), VLOOKUP(_xlfn.CONCAT($B26, $A26), GearValues, 9, 0), " ") | I26: =IF(AND(COUNTBLANK($B26)=0,NOT($B26="(Select)")), VLOOKUP(_xlfn.CONCAT($B26, $A26), GearValues, 10, 0), " ") | J26: =IF(AND(COUNTBLANK($B26)=0,NOT($B26="(Select)")), VLOOKUP(_xlfn.CONCAT($B26, $A26), GearValues, 11, 0), " ") | K26: =IF(AND(COUNTBLANK($B26)=0,NOT($B26="(Select)")), VLOOKUP(_xlfn.CONCAT($B26, $A26), GearValues, 12, 0), " ")
A27: Ear | B27: Chrysocola | C27: =IF(AND(COUNTBLANK($B27)=0,NOT($B27="(Select)")), VLOOKUP(_xlfn.CONCAT($B27, $A27), GearValues, 4, 0), " ") -> 53 | D27: =IF(AND(COUNTBLANK($B27)=0,NOT($B27="(Select)")), VLOOKUP(_xlfn.CONCAT($B27, $A27), GearValues, 5, 0), " ") | E27: =IF(AND(COUNTBLANK($B27)=0,NOT($B27="(Select)")), VLOOKUP(_xlfn.CONCAT($B27, $A27), GearValues, 6, 0), " ") | F27: =IF(AND(COUNTBLANK($B27)=0,NOT($B27="(Select)")), VLOOKUP(_xlfn.CONCAT($B27, $A27), GearValues, 7, 0), " ") -> 53 | G27: =IF(AND(COUNTBLANK($B27)=0,NOT($B27="(Select)")), VLOOKUP(_xlfn.CONCAT($B27, $A27), GearValues, 8, 0), " ") | H27: =IF(AND(COUNTBLANK($B27)=0,NOT($B27="(Select)")), VLOOKUP(_xlfn.CONCAT($B27, $A27), GearValues, 9, 0), " ") -> 75 | I27: =IF(AND(COUNTBLANK($B27)=0,NOT($B27="(Select)")), VLOOKUP(_xlfn.CONCAT($B27, $A27), GearValues, 10, 0), " ") | J27: =IF(AND(COUNTBLANK($B27)=0,NOT($B27="(Select)")), VLOOKUP(_xlfn.CONCAT($B27, $A27), GearValues, 11, 0), " ") | K27: =IF(AND(COUNTBLANK($B27)=0,NOT($B27="(Select)")), VLOOKUP(_xlfn.CONCAT($B27, $A27), GearValues, 12, 0), " ")
A28: Finger | B28: (Select) | C28: =IF(AND(COUNTBLANK($B28)=0,NOT($B28="(Select)")), VLOOKUP(_xlfn.CONCAT($B28, $A28), GearValues, 4, 0), " ") | D28: =IF(AND(COUNTBLANK($B28)=0,NOT($B28="(Select)")), VLOOKUP(_xlfn.CONCAT($B28, $A28), GearValues, 5, 0), " ") | E28: =IF(AND(COUNTBLANK($B28)=0,NOT($B28="(Select)")), VLOOKUP(_xlfn.CONCAT($B28, $A28), GearValues, 6, 0), " ") | F28: =IF(AND(COUNTBLANK($B28)=0,NOT($B28="(Select)")), VLOOKUP(_xlfn.CONCAT($B28, $A28), GearValues, 7, 0), " ") | G28: =IF(AND(COUNTBLANK($B28)=0,NOT($B28="(Select)")), VLOOKUP(_xlfn.CONCAT($B28, $A28), GearValues, 8, 0), " ") | H28: =IF(AND(COUNTBLANK($B28)=0,NOT($B28="(Select)")), VLOOKUP(_xlfn.CONCAT($B28, $A28), GearValues, 9, 0), " ") | I28: =IF(AND(COUNTBLANK($B28)=0,NOT($B28="(Select)")), VLOOKUP(_xlfn.CONCAT($B28, $A28), GearValues, 10, 0), " ") | J28: =IF(AND(COUNTBLANK($B28)=0,NOT($B28="(Select)")), VLOOKUP(_xlfn.CONCAT($B28, $A28), GearValues, 11, 0), " ") | K28: =IF(AND(COUNTBLANK($B28)=0,NOT($B28="(Select)")), VLOOKUP(_xlfn.CONCAT($B28, $A28), GearValues, 12, 0), " ")
A29: Finger | B29: (Select) | C29: =IF(AND(COUNTBLANK($B29)=0,NOT($B29="(Select)")), VLOOKUP(_xlfn.CONCAT($B29, $A29), GearValues, 4, 0), " ") | D29: =IF(AND(COUNTBLANK($B29)=0,NOT($B29="(Select)")), VLOOKUP(_xlfn.CONCAT($B29, $A29), GearValues, 5, 0), " ") | E29: =IF(AND(COUNTBLANK($B29)=0,NOT($B29="(Select)")), VLOOKUP(_xlfn.CONCAT($B29, $A29), GearValues, 6, 0), " ") | F29: =IF(AND(COUNTBLANK($B29)=0,NOT($B29="(Select)")), VLOOKUP(_xlfn.CONCAT($B29, $A29), GearValues, 7, 0), " ") | G29: =IF(AND(COUNTBLANK($B29)=0,NOT($B29="(Select)")), VLOOKUP(_xlfn.CONCAT($B29, $A29), GearValues, 8, 0), " ") | H29: =IF(AND(COUNTBLANK($B29)=0,NOT($B29="(Select)")), VLOOKUP(_xlfn.CONCAT($B29, $A29), GearValues, 9, 0), " ") | I29: =IF(AND(COUNTBLANK($B29)=0,NOT($B29="(Select)")), VLOOKUP(_xlfn.CONCAT($B29, $A29), GearValues, 10, 0), " ") | J29: =IF(AND(COUNTBLANK($B29)=0,NOT($B29="(Select)")), VLOOKUP(_xlfn.CONCAT($B29, $A29), GearValues, 11, 0), " ") | K29: =IF(AND(COUNTBLANK($B29)=0,NOT($B29="(Select)")), VLOOKUP(_xlfn.CONCAT($B29, $A29), GearValues, 12, 0), " ")
A30: Neck | B30: (Select) | C30: =IF(AND(COUNTBLANK($B30)=0,NOT($B30="(Select)")), VLOOKUP(_xlfn.CONCAT($B30, $A30), GearValues, 4, 0), " ") | D30: =IF(AND(COUNTBLANK($B30)=0,NOT($B30="(Select)")), VLOOKUP(_xlfn.CONCAT($B30, $A30), GearValues, 5, 0), " ") | E30: =IF(AND(COUNTBLANK($B30)=0,NOT($B30="(Select)")), VLOOKUP(_xlfn.CONCAT($B30, $A30), GearValues, 6, 0), " ") | F30: =IF(AND(COUNTBLANK($B30)=0,NOT($B30="(Select)")), VLOOKUP(_xlfn.CONCAT($B30, $A30), GearValues, 7, 0), " ") | G30: =IF(AND(COUNTBLANK($B30)=0,NOT($B30="(Select)")), VLOOKUP(_xlfn.CONCAT($B30, $A30), GearValues, 8, 0), " ") | H30: =IF(AND(COUNTBLANK($B30)=0,NOT($B30="(Select)")), VLOOKUP(_xlfn.CONCAT($B30, $A30), GearValues, 9, 0), " ") | I30: =IF(AND(COUNTBLANK($B30)=0,NOT($B30="(Select)")), VLOOKUP(_xlfn.CONCAT($B30, $A30), GearValues, 10, 0), " ") | J30: =IF(AND(COUNTBLANK($B30)=0,NOT($B30="(Select)")), VLOOKUP(_xlfn.CONCAT($B30, $A30), GearValues, 11, 0), " ") | K30: =IF(AND(COUNTBLANK($B30)=0,NOT($B30="(Select)")), VLOOKUP(_xlfn.CONCAT($B30, $A30), GearValues, 12, 0), " ")
A31: Back | B31: (Select) | C31: =IF(AND(COUNTBLANK($B31)=0,NOT($B31="(Select)")), VLOOKUP(_xlfn.CONCAT($B31, $A31), GearValues, 4, 0), " ") | D31: =IF(AND(COUNTBLANK($B31)=0,NOT($B31="(Select)")), VLOOKUP(_xlfn.CONCAT($B31, $A31), GearValues, 5, 0), " ") | E31: =IF(AND(COUNTBLANK($B31)=0,NOT($B31="(Select)")), VLOOKUP(_xlfn.CONCAT($B31, $A31), GearValues, 6, 0), " ") | F31: =IF(AND(COUNTBLANK($B31)=0,NOT($B31="(Select)")), VLOOKUP(_xlfn.CONCAT($B31, $A31), GearValues, 7, 0), " ") | G31: =IF(AND(COUNTBLANK($B31)=0,NOT($B31="(Select)")), VLOOKUP(_xlfn.CONCAT($B31, $A31), GearValues, 8, 0), " ") | H31: =IF(AND(COUNTBLANK($B31)=0,NOT($B31="(Select)")), VLOOKUP(_xlfn.CONCAT($B31, $A31), GearValues, 9, 0), " ") | I31: =IF(AND(COUNTBLANK($B31)=0,NOT($B31="(Select)")), VLOOKUP(_xlfn.CONCAT($B31, $A31), GearValues, 10, 0), " ") | J31: =IF(AND(COUNTBLANK($B31)=0,NOT($B31="(Select)")), VLOOKUP(_xlfn.CONCAT($B31, $A31), GearValues, 11, 0), " ") | K31: =IF(AND(COUNTBLANK($B31)=0,NOT($B31="(Select)")), VLOOKUP(_xlfn.CONCAT($B31, $A31), GearValues, 12, 0), " ")
A32: Runes | C32: Power | D32: Precision | E32: Toughness | F32: Vitality | G32: Concentration | H32: Condition Damage | I32: Expertise | J32: Ferocity | K32: Healing Power | L32: Defence
A33: Superior Rune of the Pack | C33: =IF(OR(Rune1Stat=C$3,Rune1Stat="to All Stats"),Rune1Bonus,"") -> 25 | D33: =IF(OR(Rune1Stat=D$3,Rune1Stat="to All Stats"),Rune1Bonus,"") | E33: =IF(OR(Rune1Stat=E$3,Rune1Stat="to All Stats"),Rune1Bonus,"") | F33: =IF(OR(Rune1Stat=F$3,Rune1Stat="to All Stats"),Rune1Bonus,"") | G33: =IF(OR(Rune1Stat=G$3,Rune1Stat="to All Stats"),Rune1Bonus,"") | H33: =IF(OR(Rune1Stat=H$3,Rune1Stat="to All Stats"),Rune1Bonus,"") | I33: =IF(OR(Rune1Stat=I$3,Rune1Stat="to All Stats"),Rune1Bonus,"") | J33: =IF(OR(Rune1Stat=J$3,Rune1Stat="to All Stats"),Rune1Bonus,"") | K33: =IF(OR(Rune1Stat=K$3,Rune1Stat="to All Stats"),Rune1Bonus,"")
A34: Superior Rune of Strength | C34: =IF(OR(Rune2Stat=C$3,Rune2Stat="to All Stats"),Rune2Bonus,"") -> 25 | D34: =IF(OR(Rune2Stat=D$3,Rune2Stat="to All Stats"),Rune2Bonus,"") | E34: =IF(OR(Rune2Stat=E$3,Rune2Stat="to All Stats"),Rune2Bonus,"") | F34: =IF(OR(Rune2Stat=F$3,Rune2Stat="to All Stats"),Rune2Bonus,"") | G34: =IF(OR(Rune2Stat=G$3,Rune2Stat="to All Stats"),Rune2Bonus,"") | H34: =IF(OR(Rune2Stat=H$3,Rune2Stat="to All Stats"),Rune2Bonus,"") | I34: =IF(OR(Rune2Stat=I$3,Rune2Stat="to All Stats"),Rune2Bonus,"") | J34: =IF(OR(Rune2Stat=J$3,Rune2Stat="to All Stats"),Rune2Bonus,"") | ... L34: =IF(OR(Rune2Stat=L$3,Rune2Stat="to All Stats"),Rune2Bonus,"")
A35: Superior Rune of Strength | C35: =IF(OR(Rune3Stat=C$3,Rune3Stat="to All Stats"),Rune3Bonus,"") | D35: =IF(OR(Rune3Stat=D$3,Rune3Stat="to All Stats"),Rune3Bonus,"") | E35: =IF(OR(Rune3Stat=E$3,Rune3Stat="to All Stats"),Rune3Bonus,"") | F35: =IF(OR(Rune3Stat=F$3,Rune3Stat="to All Stats"),Rune3Bonus,"") | G35: =IF(OR(Rune3Stat=G$3,Rune3Stat="to All Stats"),Rune3Bonus,"") | H35: =IF(OR(Rune3Stat=H$3,Rune3Stat="to All Stats"),Rune3Bonus,"") | I35: =IF(OR(Rune3Stat=I$3,Rune3Stat="to All Stats"),Rune3Bonus,"") | J35: =IF(OR(Rune3Stat=J$3,Rune3Stat="to All Stats"),Rune3Bonus,"") | ... L35: =IF(OR(Rune3Stat=L$3,Rune3Stat="to All Stats"),Rune3Bonus,"")
A36: Superior Rune of Strength | C36: =IF(OR(Rune4Stat=C$3,Rune4Stat="to All Stats"),Rune4Bonus,"") -> 50 | D36: =IF(OR(Rune4Stat=D$3,Rune4Stat="to All Stats"),Rune4Bonus,"") | E36: =IF(OR(Rune4Stat=E$3,Rune4Stat="to All Stats"),Rune4Bonus,"") | F36: =IF(OR(Rune4Stat=F$3,Rune4Stat="to All Stats"),Rune4Bonus,"") | G36: =IF(OR(Rune4Stat=G$3,Rune4Stat="to All Stats"),Rune4Bonus,"") | H36: =IF(OR(Rune4Stat=H$3,Rune4Stat="to All Stats"),Rune4Bonus,"") | I36: =IF(OR(Rune4Stat=I$3,Rune4Stat="to All Stats"),Rune4Bonus,"") | J36: =IF(OR(Rune4Stat=J$3,Rune4Stat="to All Stats"),Rune4Bonus,"") | ... L36: =IF(OR(Rune4Stat=L$3,Rune4Stat="to All Stats"),Rune4Bonus,"")
A37: Superior Rune of Strength | C37: =IF(OR(Rune5Stat=C$3,Rune5Stat="to All Stats"),Rune5Bonus,"") | D37: =IF(OR(Rune5Stat=D$3,Rune5Stat="to All Stats"),Rune5Bonus,"") | E37: =IF(OR(Rune5Stat=E$3,Rune5Stat="to All Stats"),Rune5Bonus,"") | F37: =IF(OR(Rune5Stat=F$3,Rune5Stat="to All Stats"),Rune5Bonus,"") | G37: =IF(OR(Rune5Stat=G$3,Rune5Stat="to All Stats"),Rune5Bonus,"") | H37: =IF(OR(Rune5Stat=H$3,Rune5Stat="to All Stats"),Rune5Bonus,"") | I37: =IF(OR(Rune5Stat=I$3,Rune5Stat="to All Stats"),Rune5Bonus,"") | J37: =IF(OR(Rune5Stat=J$3,Rune5Stat="to All Stats"),Rune5Bonus,"") | ... L37: =IF(OR(Rune5Stat=L$3,Rune5Stat="to All Stats"),Rune5Bonus,"")
A38: (Select) | C38: =IF(OR(Rune6Stat=C$3,Rune6Stat="to All Stats"),Rune6Bonus,"") | D38: =IF(OR(Rune6Stat=D$3,Rune6Stat="to All Stats"),Rune6Bonus,"") | E38: =IF(OR(Rune6Stat=E$3,Rune6Stat="to All Stats"),Rune6Bonus,"") | F38: =IF(OR(Rune6Stat=F$3,Rune6Stat="to All Stats"),Rune6Bonus,"") | G38: =IF(OR(Rune6Stat=G$3,Rune6Stat="to All Stats"),Rune6Bonus,"") | H38: =IF(OR(Rune6Stat=H$3,Rune6Stat="to All Stats"),Rune6Bonus,"") | I38: =IF(OR(Rune6Stat=I$3,Rune6Stat="to All Stats"),Rune6Bonus,"") | J38: =IF(OR(Rune6Stat=J$3,Rune6Stat="to All Stats"),Rune6Bonus,"") | ... L38: =IF(OR(Rune6Stat=L$3,Rune6Stat="to All Stats"),Rune6Bonus,"")
A39: Jewels | C39: Power | D39: Precision | E39: Toughness | F39: Vitality | G39: Concentration | H39: Condition Damage | I39: Expertise | J39: Ferocity | K39: Healing Power | L39: Defence
A40: Exquisite Azurite Jewel | C40: {=_xlfn.LET(_xlpm.check,VLOOKUP($A40,Jewels!$A$1:$N$27,6,0),IF(AND(COUNTBLANK($A40)=0,NOT($A40="(Select)")),IF(_xlpm.check="","",_xlpm.check),""))} -> 15 | D40: {=_xlfn.LET(_xlpm.check,VLOOKUP($A40,Jewels!$A$1:$N$27,7,0),IF(AND(COUNTBLANK($A40)=0,NOT($A40="(Select)")),IF(_xlpm.check="","",_xlpm.check),""))} | E40: {=_xlfn.LET(_xlpm.check,VLOOKUP($A40,Jewels!$A$1:$N$27,8,0),IF(AND(COUNTBLANK($A40)=0,NOT($A40="(Select)")),IF(_xlpm.check="","",_xlpm.check),""))} -> 15 | F40: {=_xlfn.LET(_xlpm.check,VLOOKUP($A40,Jewels!$A$1:$N$27,9,0),IF(AND(COUNTBLANK($A40)=0,NOT($A40="(Select)")),IF(_xlpm.check="","",_xlpm.check),""))} -> 25 | G40: {=_xlfn.LET(_xlpm.check,VLOOKUP($A40,Jewels!$A$1:$N$27,10,0),IF(AND(COUNTBLANK($A40)=0,NOT($A40="(Select)")),IF(_xlpm.check="","",_xlpm.check),""))} | H40: {=_xlfn.LET(_xlpm.check,VLOOKUP($A40,Jewels!$A$1:$N$27,11,0),IF(AND(COUNTBLANK($A40)=0,NOT($A40="(Select)")),IF(_xlpm.check="","",_xlpm.check),""))} | I40: {=_xlfn.LET(_xlpm.check,VLOOKUP($A40,Jewels!$A$1:$N$27,12,0),IF(AND(COUNTBLANK($A40)=0,NOT($A40="(Select)")),IF(_xlpm.check="","",_xlpm.check),""))} | J40: {=_xlfn.LET(_xlpm.check,VLOOKUP($A40,Jewels!$A$1:$N$27,13,0),IF(AND(COUNTBLANK($A40)=0,NOT($A40="(Select)")),IF(_xlpm.check="","",_xlpm.check),""))} | K40: {=_xlfn.LET(_xlpm.check,VLOOKUP($A40,Jewels!$A$1:$N$27,14,0),IF(AND(COUNTBLANK($A40)=0,NOT($A40="(Select)")),IF(_xlpm.check="","",_xlpm.check),""))}
...

Sheet Trait Selection
B1: =Spec1 -> Illusions | F1: =Spec2 -> Inspiration | J1: =Spec3 -> Troubadour
B2: Name | C2: Apply Condition | D2: Stacks | E2: Effect | F2: Name | G2: Apply Condition | H2: Stacks | I2: Effect | J2: Name | K2: Apply Condition | L2: Stacks | M2: Effect
A3: Minor Adept | B3: =Spec1MinorAdept -> Cry of Pain | C3: (Select) | D3: 0 | E3: {=_xlfn.LET(_xlpm.val,VLOOKUP(Spec1MinorAdept,TraitTable,5,0),IF(ISNA(_xlpm.val),"",_xlpm.val))} -> Shatter skill 2 inflicts more stacks of confusion for an increased duration. | F3: =Spec2MinorAdept -> Mender's Purity | G3: (Select) | H3: 0 | I3: {=_xlfn.LET(_xlpm.val,VLOOKUP(Spec2MinorAdept,TraitTable,5,0),IF(ISNA(_xlpm.val),"",_xlpm.val))} -> Cast Lesser Power Cleanse when you use a healing skill. | J3: =Spec3MinorAdept -> Wandering Minstrel | K3: (Select) | L3: 0 | M3: {=_xlfn.LET(_xlpm.val,VLOOKUP(Spec3MinorAdept,TraitTable,5,0),IF(ISNA(_xlpm.val),"",_xlpm.val))} -> Build up notes instead of summoning illusions. Shatters are replaced by instrument skills, which consume notes to continue playing. Gain access to Tales. While out of combat, you will automatically stock a blade [ sic ] every 10 seconds.
A4: Major Adept | B4: =IF(Spec1MajorAdept=0,"",Spec1MajorAdept) -> Persistence of Memory | C4: (Select) | D4: 0 | E4: {=_xlfn.LET(_xlpm.val,VLOOKUP(Spec1MajorAdept,TraitTable,5,0),IF(ISNA(_xlpm.val),"",_xlpm.val))} -> When a phantasm becomes a clone, it transfers its boons to you. | F4: =IF(Spec2MajorAdept=0,"",Spec2MajorAdept) -> (Select) | G4: (Select) | H4: 0 | I4: {=_xlfn.LET(_xlpm.val,VLOOKUP(Spec2MajorAdept,TraitTable,5,0),IF(ISNA(_xlpm.val),"",_xlpm.val))} | J4: =IF(Spec3MajorAdept=0,"",Spec3MajorAdept) -> Illusionary Defense | K4: (Select) | L4: 0 | M4: {=_xlfn.LET(_xlpm.val,VLOOKUP(Spec3MajorAdept,TraitTable,5,0),IF(ISNA(_xlpm.val),"",_xlpm.val))} -> Grant protection to nearby allies when you use Shatter skill 2.
A5: Minor Master | B5: =Spec1MinorMaster -> Compounding Power | C5: Illusion created | D5: 2 | E5: {=_xlfn.LET(_xlpm.val,VLOOKUP(Spec1MinorMaster,TraitTable,5,0),IF(ISNA(_xlpm.val),"",_xlpm.val))} -> Creating an illusion increases your outgoing damage and condition damage for a short duration. Virtuoso : Triggers when stocking a blade. | F5: =Spec2MinorMaster -> Inspiring Distortion | G5: (Select) | H5: 0 | I5: {=_xlfn.LET(_xlpm.val,VLOOKUP(Spec2MinorMaster,TraitTable,5,0),IF(ISNA(_xlpm.val),"",_xlpm.val))} -> Grant aegis to other nearby allies whenever you give yourself distortion or use Shatter skill 4. | J5: =Spec3MinorMaster -> Symphonic Resonance | K5: Lute playing in background | L5: 0 | M5: {=_xlfn.LET(_xlpm.val,VLOOKUP(Spec3MinorMaster,TraitTable,5,0),IF(ISNA(_xlpm.val),"",_xlpm.val))} -> Instruments provide bonuses while playing in the background.
A6: Major Master | B6: =IF(Spec1MajorMaster=0,"",Spec1MajorMaster) -> (Select) | C6: (Select) | D6: 0 | E6: {=_xlfn.LET(_xlpm.val,VLOOKUP(Spec1MajorMaster,TraitTable,5,0),IF(ISNA(_xlpm.val),"",_xlpm.val))} | F6: =IF(Spec2MajorMaster=0,"",Spec2MajorMaster) -> Warden's Feedback | G6: (Select) | H6: 0 | I6: {=_xlfn.LET(_xlpm.val,VLOOKUP(Spec2MajorMaster,TraitTable,5,0),IF(ISNA(_xlpm.val),"",_xlpm.val))} -> Focus weapon skills reflect projectiles. Reduces recharge on focus weapon skills. | J6: =IF(Spec3MajorMaster=0,"",Spec3MajorMaster) -> (Select) | K6: (Select) | L6: 0 | M6: {=_xlfn.LET(_xlpm.val,VLOOKUP(Spec3MajorMaster,TraitTable,5,0),IF(ISNA(_xlpm.val),"",_xlpm.val))}
A7: Minor Grandmaster | B7: =Spec1MinorGrandmaster -> Master of Misdirection | C7: (Select) | D7: 0 | E7: {=_xlfn.LET(_xlpm.val,VLOOKUP(Spec1MinorGrandmaster,TraitTable,5,0),IF(ISNA(_xlpm.val),"",_xlpm.val))} -> Shatter skills gain recharge reduction. | F7: =Spec2MinorGrandmaster -> Illusionary Inspiration | G7: (Select) | H7: 0 | I7: {=_xlfn.LET(_xlpm.val,VLOOKUP(Spec2MinorGrandmaster,TraitTable,5,0),IF(ISNA(_xlpm.val),"",_xlpm.val))} -> Increase healing to other allies. Summoning an illusion heals all allies around you. Virtuoso : Triggers when stocking a blade. | J7: =Spec3MinorGrandmaster -> Harmonize | K7: (Select) | L7: 0 | M7: {=_xlfn.LET(_xlpm.val,VLOOKUP(Spec3MinorGrandmaster,TraitTable,5,0),IF(ISNA(_xlpm.val),"",_xlpm.val))} -> Gain a note when you use a phantasm skill.
A8: Major Grandmaster | B8: =IF(Spec1MajorGrandmaster=0,"",Spec1MajorGrandmaster) -> (Select) | C8: (Select) | D8: 0 | E8: {=_xlfn.LET(_xlpm.val,VLOOKUP(Spec1MajorGrandmaster,TraitTable,5,0),IF(ISNA(_xlpm.val),"",_xlpm.val))} | F8: =IF(Spec2MajorGrandmaster=0,"",Spec2MajorGrandmaster) -> (Select) | G8: (Select) | H8: 0 | I8: {=_xlfn.LET(_xlpm.val,VLOOKUP(Spec2MajorGrandmaster,TraitTable,5,0),IF(ISNA(_xlpm.val),"",_xlpm.val))} | J8: =IF(Spec3MajorGrandmaster=0,"",Spec3MajorGrandmaster) -> (Select) | K8: Instrument playing | L8: 0 | M8: {=_xlfn.LET(_xlpm.val,VLOOKUP(Spec3MajorGrandmaster,TraitTable,5,0),IF(ISNA(_xlpm.val),"",_xlpm.val))}
N9: Legend
N10: Condition/Stacks active
N11: Condition/Stacks available but inactive
A12: Power | B12: ='Build & Totals'!B56 -> 1672.94 | C12: Health | D12: ='Build & Totals'!D56 -> 17482
A13: Precision* | B13: ='Build & Totals'!B57 -> 1594 (876) | C13: Armor | D13: ='Build & Totals'!D57 -> 2128
A14: Toughness | B14: ='Build & Totals'!B58 -> 1221 | C14: Critical Chance | D14: ='Build & Totals'!D58 -> 0.58285714
A15: Vitality | B15: ='Build & Totals'!B59 -> 1156 | C15: Critical Damage | D15: ='Build & Totals'!D59 -> 1.6653333
A16: Concentration | B16: ='Build & Totals'!B60 -> 10 (1490) | C16: Boon Duration | D16: ='Build & Totals'!D60 -> 0.0066666667
A17: Condition Damage | B17: ='Build & Totals'!B61 -> 343.2 | C17: Condition Duration | D17: ='Build & Totals'!D61 -> 0.17333333
A18: Expertise | B18: ='Build & Totals'!B62 -> 260 (1240)
A19: Ferocity | B19: ='Build & Totals'!B63 -> 248
A20: Healing Power | B20: ='Build & Totals'!B64 -> 47

Sheet Full Traits
A1: Name | B1: Class | C1: Specialisation | D1: Tier | E1: Description | F1: Filter
A2: Zealot's Resolution | B2: Guardian | C2: Zeal | D2: Minor Adept | E2: Cast Lesser Symbol of Resolution when you are struck while below the health threshold. | F2: =IF(AND(COUNTIF('Build & Totals'!$A$4:$B$12,$C2)>=1,Class=$B2),$A2,"") | H2: Selected Major Trait
A3: Wrathful Spirit | B3: Guardian | C3: Zeal | D3: Major Adept | E3: Aegis grants boons when it ends. | F3: =IF(AND(COUNTIF('Build & Totals'!$A$4:$B$12,$C3)>=1,Class=$B3),$A3,"") | H3: Selected Minor Trait
A4: Fiery Wrath | B4: Guardian | C4: Zeal | D4: Major Adept | E4: Deal increased strike damage to burning foes. | F4: =IF(AND(COUNTIF('Build & Totals'!$A$4:$B$12,$C4)>=1,Class=$B4),$A4,"")
A5: Zealous Scepter | B5: Guardian | C5: Zeal | D5: Major Adept | E5: Gain might when your Virtue skill 1 passive effect triggers; gain more might while wielding a scepter. | F5: =IF(AND(COUNTIF('Build & Totals'!$A$4:$B$12,$C5)>=1,Class=$B5),$A5,"")
A6: Symbolic Exposure | B6: Guardian | C6: Zeal | D6: Minor Master | E6: Symbols inflict vulnerability on foes. Deal increased strike damage to vulnerable foes. | F6: =IF(AND(COUNTIF('Build & Totals'!$A$4:$B$12,$C6)>=1,Class=$B6),$A6,"")
A7: Furious Focus | B7: Guardian | C7: Zeal | D7: Major Master | E7: While you have fury, your attacks inflict vulnerability. | F7: =IF(AND(COUNTIF('Build & Totals'!$A$4:$B$12,$C7)>=1,Class=$B7),$A7,"")
A8: Zealous Blade | B8: Guardian | C8: Zeal | D8: Major Master | E8: Your power is increased. Gain additional power while wielding a greatsword. Your greatsword skills have reduced recharge. | F8: =IF(AND(COUNTIF('Build & Totals'!$A$4:$B$12,$C8)>=1,Class=$B8),$A8,"")
A9: Kindled Zeal | B9: Guardian | C9: Zeal | D9: Major Master | E9: Gain condition damage based on your power. | F9: =IF(AND(COUNTIF('Build & Totals'!$A$4:$B$12,$C9)>=1,Class=$B9),$A9,"")
A10: Symbolic Power | B10: Guardian | C10: Zeal | D10: Minor Grandmaster | E10: Symbols deal increased strike damage. | F10: =IF(AND(COUNTIF('Build & Totals'!$A$4:$B$12,$C10)>=1,Class=$B10),$A10,"")
A11: Eternal Armory | B11: Guardian | C11: Zeal | D11: Major Grandmaster | E11: Spirit Weapons gain additional casts and burn foes with their first strike. | F11: =IF(AND(COUNTIF('Build & Totals'!$A$4:$B$12,$C11)>=1,Class=$B11),$A11,"")
A12: Shattered Aegis | B12: Guardian | C12: Zeal | D12: Major Grandmaster | E12: When an aegis you applied blocks an attack, it unleashes a Mystic Rebuke. | F12: =IF(AND(COUNTIF('Build & Totals'!$A$4:$B$12,$C12)>=1,Class=$B12),$A12,"")
A13: Symbolic Avenger | B13: Guardian | C13: Zeal | D13: Major Grandmaster | E13: Your strike damage is increased whenever your Symbols hit a foe. | F13: =IF(AND(COUNTIF('Build & Totals'!$A$4:$B$12,$C13)>=1,Class=$B13),$A13,"")
A14: Justice is Blind | B14: Guardian | C14: Radiance | D14: Minor Adept | E14: Gain a light aura and blind nearby foes when you activate Virtue skill 1. | F14: =IF(AND(COUNTIF('Build & Totals'!$A$4:$B$12,$C14)>=1,Class=$B14),$A14,"")
A15: Inner Fire | B15: Guardian | C15: Radiance | D15: Major Adept | E15: Gain fury when you strike a foe that has burning stacks over the threshold. | F15: =IF(AND(COUNTIF('Build & Totals'!$A$4:$B$12,$C15)>=1,Class=$B15),$A15,"")
... A1000: Soul Twisting | B1000: Necromancer | C1000: Ritualist | D1000: Major Grandmaster | E1000: The first spirit skill you use when entering ritualist's shroud recharges instantly. | F1000: =IF(AND(COUNTIF('Build & Totals'!$A$4:$B$12,$C1000)>=1,Class=$B1000),$A1000,"")

Sheet Trait Stats
A1: Name | B1: Class | C1: Specialisation | D1: Tier | E1: Stat | F1: Amount | G1: Type 1 | H1: Type 2 | I1: Conditional? | J1: Condition | K1: Affecting Stat/Boon | L1: Note | M1: Max Stacks
A2: Aeromancer's Training | B2: Elementalist | C2: Air | D2: Minor Grandmaster | E2: Ferocity | F2: 150 | G2: Flat | L2: +150 Ferocity
A3: Aeromancer's Training | B3: Elementalist | C3: Air | D3: Minor Grandmaster | E3: Ferocity | F3: 150 | G3: Flat | L3: +150 Ferocity
A4: Arcane Lightning | B4: Elementalist | C4: Arcane | D4: Major Grandmaster | E4: Ferocity | F4: 150 | G4: Flat | I4: Yes | J4: Arcane Skill used | L4: +150 Ferocity on Arcane Skill use
A5: Burning Rage | B5: Elementalist | C5: Fire | D5: Major Master | E5: Condition Damage | F5: 180 | G5: Flat | L5: +180 Condition Damage
A6: Elemental Enhancement | B6: Elementalist | C6: Arcane | D6: Minor Grandmaster | E6: Concentration | F6: 180 | G6: Flat | L6: +180 Concentration
A7: Elemental Polyphony | B7: Elementalist | C7: Weaver | D7: Minor Grandmaster | E7: Power | F7: 200 | G7: Flat | I7: Yes | J7: Player attuned to Fire | L7: +200 Power while attuned to Fire
A8: Elemental Polyphony | B8: Elementalist | C8: Weaver | D8: Minor Grandmaster | E8: Healing Power | F8: 200 | G8: Flat | I8: Yes | J8: Player attuned to Water | L8: +200 Healing Power while attuned to Water
A9: Elemental Polyphony | B9: Elementalist | C9: Weaver | D9: Minor Grandmaster | E9: Ferocity | F9: 200 | G9: Flat | I9: Yes | J9: Player attuned to Air | L9: +200 Ferocity while attuned to Air
A10: Elemental Polyphony | B10: Elementalist | C10: Weaver | D10: Minor Grandmaster | E10: Vitality | F10: 200 | G10: Flat | I10: Yes | J10: Player attuned to Earth | L10: +200 Vitality while attuned to Earth
A11: Elements of Rage | B11: Elementalist | C11: Weaver | D11: Major Grandmaster | E11: Condition Damage | F11: 0.07 | G11: Percentage | I11: Yes | J11: Attuned to single element | L11: +7% Condition Damage when attuned to single element
A12: Elements of Rage | B12: Elementalist | C12: Weaver | D12: Major Grandmaster | E12: Precision | F12: 0.13 | G12: Percentage | H12: Derived | K12: Vitality | L12: +Precision, 13% of Vitality
A13: Enhanced Potency | B13: Elementalist | C13: Evoker | D13: Minor Master | E13: Condition Damage | F13: 5 | G13: Flat | H13: Boon Enhancement | I13: Yes | J13: Fox familiar | L13: +5 Condition Damage from Might stacks from Fox familiar
A14: Enhanced Potency | B14: Elementalist | C14: Evoker | D14: Minor Master | E14: Healing Power | F14: 0.2 | G14: Percentage | H14: Boon Enhancement | I14: Yes | J14: Otter familiar | K14: Regeneration | L14: +20% Healing Power from Regeneration from Otter familiar
A15: Enhanced Potency | B15: Elementalist | C15: Evoker | D15: Minor Master | E15: Crit Chance | F15: 0.15 | G15: Flat | H15: Boon Enhancement | I15: Yes | J15: Hare familiar | K15: Fury | L15: +15% Critical Chance from Fury from Hare familiar
A16: Familiar's Focus | B16: Elementalist | C16: Evoker | D16: Major Master | E16: Condition Damage | F16: 0.18 | G16: Percentage | I16: Yes | J16: Fox familiar | L16: +25% Condition Damage from Familiar's Prowess Fox familiar (overwrite)
A17: Familiar's Prowess | B17: Elementalist | C17: Evoker | D17: Minor Grandmaster | E17: Condition Damage | F17: 0.07 | G17: Percentage | I17: Yes | J17: Fox familiar | L17: +7% Condition Damage from Fox familiar
A18: Ferocious Winds | B18: Elementalist | C18: Air | D18: Major Adept | E18: Ferocity | F18: 0.07 | G18: Percentage | H18: Derived | K18: Precision | L18: +Ferocity, 7% of Precision
A19: Fresh Air | B19: Elementalist | C19: Air | D19: Major Grandmaster | E19: Ferocity | F19: 250 | G19: Flat | I19: Yes | J19: Player attuned to Air | L19: +250 Ferocity while attuned to Air
A20: Gathered Focus | B20: Elementalist | C20: Tempest | D20: Minor Master | E20: Concentration | F20: 240 | G20: Flat | L20: +240 Concentration
A21: Master's Fortitude | B21: Elementalist | C21: Weaver | D21: Major Adept | E21: Vitality | F21: 120 | G21: Flat | I21: Yes | J21: Sword equipped | L21: +120 Vitality with Sword equipped
A22: Master's Fortitude | B22: Elementalist | C22: Weaver | D22: Major Adept | E22: Vitality | F22: 0.05 | G22: Percentage | H22: Derived | K22: Power | L22: +Vitality, 5% of Power
A23: Master's Fortitude | B23: Elementalist | C23: Weaver | D23: Major Adept | E23: Vitality | F23: 0.05 | G23: Percentage | H23: Derived | K23: Condition Damage | L23: +Vitality, 5% of Condition Damage
A24: Power Overwhelming | B24: Elementalist | C24: Fire | D24: Major Master | E24: Power | F24: 150 | G24: Flat | I24: Yes | J24: 10+ stacks of Might | L24: +150 Power at 10 stacks of Might
A25: Raging Storm | B25: Elementalist | C25: Air | D25: Major Master | E25: Ferocity | F25: 180 | G25: Flat | H25: Boon Enhancement | K25: Fury | L25: +180 Ferocity from Fury
A26: Soothing Power | B26: Elementalist | C26: Water | D26: Major Grandmaster | E26: Vitality | F26: 300 | G26: Flat | L26: +300 Vitality
A27: Strength of Stone | B27: Elementalist | C27: Earth | D27: Major Master | E27: Condition Damage | F27: 0.1 | G27: Percentage | H27: Derived | K27: Toughness | L27: +Condition Damage, 10% of Toughness
A28: Weaver's Prowess | B28: Elementalist | C28: Weaver | D28: Major Master | E28: Condition Damage | F28: 0.05 | G28: Percentage | I28: Yes | J28: Recently attuned to different element | L28: +5% Condition Damage when attuning to different element
A29: Weaver's Prowess | B29: Elementalist | C29: Weaver | D29: Major Master | E29: Condition Duration | F29: 0.2 | G29: Flat | I29: Yes | J29: Recently attuned to different element | L29: +20% Condition Duration when attuning to different element
A30: Zephyr's Speed | B30: Elementalist | C30: Air | D30: Minor Adept | E30: Crit Chance | F30: 0.05 | G30: Flat | L30: +5% Critical Chance
A31: Applied Force | B31: Engineer | C31: Scrapper | D31: Major Grandmaster | E31: Power | F31: 30 | G31: Flat | H31: Boon Enhancement | K31: Might | L31: +30 Power from Might stacks
A32: Blast Shield | B32: Engineer | C32: Explosives | D32: Major Master | E32: Vitality | F32: 0.1 | G32: Percentage | H32: Derived | K32: Power | L32: +Vitality, 10% of Power
A33: Chemical Rounds | B33: Engineer | C33: Firearms | D33: Major Adept | E33: Condition Damage | F33: 120 | G33: Flat | L33: +120 Condition Damage
A34: Chemical Rounds | B34: Engineer | C34: Firearms | D34: Major Adept | E34: Condition Duration | F34: 0.33 | G34: Flat | I34: Yes | J34: Pistol Skill | L34: +33% Condition Duration on Pistol Skills
A35: Compounding Chemicals | B35: Engineer | C35: Alchemy | D35: Minor Grandmaster | E35: Concentration | F35: 240 | G35: Flat | L35: +240 Concentration
A36: Energy Amplifier | B36: Engineer | C36: Inventions | D36: Minor Grandmaster | E36: Power | F36: 250 | G36: Flat | H36: Boon Enhancement | K36: Regeneration | L36: +250 Power from Regeneration
A37: Energy Amplifier | B37: Engineer | C37: Inventions | D37: Minor Grandmaster | E37: Healing Power | F37: 250 | G37: Flat | H37: Boon Enhancement | K37: Regeneration | L37: +250 Healing Power from Regeneration
A38: Explosive Temper | B38: Engineer | C38: Explosives | D38: Major Master | E38: Ferocity | F38: 20 | G38: Flat | H38: Stacking | I38: Yes | J38: Explosion hit | L38: Stacking +20 Ferocity on Explosion hit | M38: 10
A39: Grand Entrance | B39: Engineer | C39: Explosives | D39: Major Grandmaster | E39: Crit Chance | F39: 0.1 | G39: Flat | I39: Yes | J39: Hit with Explosive Entrance | L39: +10% Critical Chance from Explosive Entrance
A40: Health Insurance | B40: Engineer | C40: Alchemy | D40: Major Adept | E40: Healing Power | F40: 0.2 | G40: Percentage | I40: Yes | J40: Med Kit equipped | L40: +20% Healing Power with Med Kit equipped
...

Sheet Attributes & Prefixes
A1: Prefixes and Attributes | H1: Prefixes & Values
A2: Prefix | B2: Major | C2: Major 2 | D2: Minor | E2: Minor 2 | F2: Filtered | H2: Ref | I2: Prefix | J2: Slot | K2: Power | L2: Precision | M2: Toughness | N2: Vitality | O2: Concentration | P2: Condition Damage | Q2: Expertise | R2: Ferocity | S2: Healing Power
F3: (Select) | H3: =_xlfn.CONCAT(I$3,J3) -> ApostateWeapon (1H) | I3: =A4 -> Apostate | J3: Weapon (1H) | K3: {=IF(COUNTIF($B$4:$E$4, K$2)>0, _xlfn.IFS(COUNTIF($B$4:$C$4, K$2)>0, VLOOKUP($J3,'Gear Values'!$A$2:$E$13, IF(COUNTBLANK('Attributes & Prefixes'!$B$4:$C$4)>0, "2", "3"), 0), COUNTIF($D$4:$E$4, K$2)>0, VLOOKUP($J3,'Gear Values'!$A$2:$E$13, IF(COUNTBLANK('Attributes & Prefixes'!$B$4:$C$4)>0, "4", "5"), 0)), "")} | L3: {=IF(COUNTIF($B$4:$E$4, L$2)>0, _xlfn.IFS(COUNTIF($B$4:$C$4, L$2)>0, VLOOKUP($J3,'Gear Values'!$A$2:$E$13, IF(COUNTBLANK('Attributes & Prefixes'!$B$4:$C$4)>0, "2", "3"), 0), COUNTIF($D$4:$E$4, L$2)>0, VLOOKUP($J3,'Gear Values'!$A$2:$E$13, IF(COUNTBLANK('Attributes & Prefixes'!$B$4:$C$4)>0, "4", "5"), 0)), "")} | M3: {=IF(COUNTIF($B$4:$E$4, M$2)>0, _xlfn.IFS(COUNTIF($B$4:$C$4, M$2)>0, VLOOKUP($J3,'Gear Values'!$A$2:$E$13, IF(COUNTBLANK('Attributes & Prefixes'!$B$4:$C$4)>0, "2", "3"), 0), COUNTIF($D$4:$E$4, M$2)>0, VLOOKUP($J3,'Gear Values'!$A$2:$E$13, IF(COUNTBLANK('Attributes & Prefixes'!$B$4:$C$4)>0, "4", "5"), 0)), "")} -> 85 | N3: {=IF(COUNTIF($B$4:$E$4, N$2)>0, _xlfn.IFS(COUNTIF($B$4:$C$4, N$2)>0, VLOOKUP($J3,'Gear Values'!$A$2:$E$13, IF(COUNTBLANK('Attributes & Prefixes'!$B$4:$C$4)>0, "2", "3"), 0), COUNTIF($D$4:$E$4, N$2)>0, VLOOKUP($J3,'Gear Values'!$A$2:$E$13, IF(COUNTBLANK('Attributes & Prefixes'!$B$4:$C$4)>0, "4", "5"), 0)), "")} | O3: {=IF(COUNTIF($B$4:$E$4, O$2)>0, _xlfn.IFS(COUNTIF($B$4:$C$4, O$2)>0, VLOOKUP($J3,'Gear Values'!$A$2:$E$13, IF(COUNTBLANK('Attributes & Prefixes'!$B$4:$C$4)>0, "2", "3"), 0), COUNTIF($D$4:$E$4, O$2)>0, VLOOKUP($J3,'Gear Values'!$A$2:$E$13, IF(COUNTBLANK('Attributes & Prefixes'!$B$4:$C$4)>0, "4", "5"), 0)), "")} | P3: {=IF(COUNTIF($B$4:$E$4, P$2)>0, _xlfn.IFS(COUNTIF($B$4:$C$4, P$2)>0, VLOOKUP($J3,'Gear Values'!$A$2:$E$13, IF(COUNTBLANK('Attributes & Prefixes'!$B$4:$C$4)>0, "2", "3"), 0), COUNTIF($D$4:$E$4, P$2)>0, VLOOKUP($J3,'Gear Values'!$A$2:$E$13, IF(COUNTBLANK('Attributes & Prefixes'!$B$4:$C$4)>0, "4", "5"), 0)), "")} -> 120 | Q3: {=IF(COUNTIF($B$4:$E$4, Q$2)>0, _xlfn.IFS(COUNTIF($B$4:$C$4, Q$2)>0, VLOOKUP($J3,'Gear Values'!$A$2:$E$13, IF(COUNTBLANK('Attributes & Prefixes'!$B$4:$C$4)>0, "2", "3"), 0), COUNTIF($D$4:$E$4, Q$2)>0, VLOOKUP($J3,'Gear Values'!$A$2:$E$13, IF(COUNTBLANK('Attributes & Prefixes'!$B$4:$C$4)>0, "4", "5"), 0)), "")} | R3: {=IF(COUNTIF($B$4:$E$4, R$2)>0, _xlfn.IFS(COUNTIF($B$4:$C$4, R$2)>0, VLOOKUP($J3,'Gear Values'!$A$2:$E$13, IF(COUNTBLANK('Attributes & Prefixes'!$B$4:$C$4)>0, "2", "3"), 0), COUNTIF($D$4:$E$4, R$2)>0, VLOOKUP($J3,'Gear Values'!$A$2:$E$13, IF(COUNTBLANK('Attributes & Prefixes'!$B$4:$C$4)>0, "4", "5"), 0)), "")} | S3: {=IF(COUNTIF($B$4:$E$4, S$2)>0, _xlfn.IFS(COUNTIF($B$4:$C$4, S$2)>0, VLOOKUP($J3,'Gear Values'!$A$2:$E$13, IF(COUNTBLANK('Attributes & Prefixes'!$B$4:$C$4)>0, "2", "3"), 0), COUNTIF($D$4:$E$4, S$2)>0, VLOOKUP($J3,'Gear Values'!$A$2:$E$13, IF(COUNTBLANK('Attributes & Prefixes'!$B$4:$C$4)>0, "4", "5"), 0)), "")} -> 85
A4: Apostate | B4: Condition Damage | D4: Toughness | E4: Healing Power | F4: =IF(OR(COUNTBLANK(AttributeFilter) = 1,AttributeFilter="(Select)"), A4, IF(COUNTIF(B4:E4, AttributeFilter)>0, A4, "")) -> Apostate | H4: =_xlfn.CONCAT(I$3,J4) -> ApostateWeapon (2H) | J4: Weapon (2H) | K4: {=IF(COUNTIF($B$4:$E$4, K$2)>0, _xlfn.IFS(COUNTIF($B$4:$C$4, K$2)>0, VLOOKUP($J4,'Gear Values'!$A$2:$E$13, IF(COUNTBLANK('Attributes & Prefixes'!$B$4:$C$4)>0, "2", "3"), 0), COUNTIF($D$4:$E$4, K$2)>0, VLOOKUP($J4,'Gear Values'!$A$2:$E$13, IF(COUNTBLANK('Attributes & Prefixes'!$B$4:$C$4)>0, "4", "5"), 0)), "")} | L4: {=IF(COUNTIF($B$4:$E$4, L$2)>0, _xlfn.IFS(COUNTIF($B$4:$C$4, L$2)>0, VLOOKUP($J4,'Gear Values'!$A$2:$E$13, IF(COUNTBLANK('Attributes & Prefixes'!$B$4:$C$4)>0, "2", "3"), 0), COUNTIF($D$4:$E$4, L$2)>0, VLOOKUP($J4,'Gear Values'!$A$2:$E$13, IF(COUNTBLANK('Attributes & Prefixes'!$B$4:$C$4)>0, "4", "5"), 0)), "")} | M4: {=IF(COUNTIF($B$4:$E$4, M$2)>0, _xlfn.IFS(COUNTIF($B$4:$C$4, M$2)>0, VLOOKUP($J4,'Gear Values'!$A$2:$E$13, IF(COUNTBLANK('Attributes & Prefixes'!$B$4:$C$4)>0, "2", "3"), 0), COUNTIF($D$4:$E$4, M$2)>0, VLOOKUP($J4,'Gear Values'!$A$2:$E$13, IF(COUNTBLANK('Attributes & Prefixes'!$B$4:$C$4)>0, "4", "5"), 0)), "")} -> 171 | N4: {=IF(COUNTIF($B$4:$E$4, N$2)>0, _xlfn.IFS(COUNTIF($B$4:$C$4, N$2)>0, VLOOKUP($J4,'Gear Values'!$A$2:$E$13, IF(COUNTBLANK('Attributes & Prefixes'!$B$4:$C$4)>0, "2", "3"), 0), COUNTIF($D$4:$E$4, N$2)>0, VLOOKUP($J4,'Gear Values'!$A$2:$E$13, IF(COUNTBLANK('Attributes & Prefixes'!$B$4:$C$4)>0, "4", "5"), 0)), "")} | O4: {=IF(COUNTIF($B$4:$E$4, O$2)>0, _xlfn.IFS(COUNTIF($B$4:$C$4, O$2)>0, VLOOKUP($J4,'Gear Values'!$A$2:$E$13, IF(COUNTBLANK('Attributes & Prefixes'!$B$4:$C$4)>0, "2", "3"), 0), COUNTIF($D$4:$E$4, O$2)>0, VLOOKUP($J4,'Gear Values'!$A$2:$E$13, IF(COUNTBLANK('Attributes & Prefixes'!$B$4:$C$4)>0, "4", "5"), 0)), "")} | P4: {=IF(COUNTIF($B$4:$E$4, P$2)>0, _xlfn.IFS(COUNTIF($B$4:$C$4, P$2)>0, VLOOKUP($J4,'Gear Values'!$A$2:$E$13, IF(COUNTBLANK('Attributes & Prefixes'!$B$4:$C$4)>0, "2", "3"), 0), COUNTIF($D$4:$E$4, P$2)>0, VLOOKUP($J4,'Gear Values'!$A$2:$E$13, IF(COUNTBLANK('Attributes & Prefixes'!$B$4:$C$4)>0, "4", "5"), 0)), "")} -> 239 | Q4: {=IF(COUNTIF($B$4:$E$4, Q$2)>0, _xlfn.IFS(COUNTIF($B$4:$C$4, Q$2)>0, VLOOKUP($J4,'Gear Values'!$A$2:$E$13, IF(COUNTBLANK('Attributes & Prefixes'!$B$4:$C$4)>0, "2", "3"), 0), COUNTIF($D$4:$E$4, Q$2)>0, VLOOKUP($J4,'Gear Values'!$A$2:$E$13, IF(COUNTBLANK('Attributes & Prefixes'!$B$4:$C$4)>0, "4", "5"), 0)), "")} | R4: {=IF(COUNTIF($B$4:$E$4, R$2)>0, _xlfn.IFS(COUNTIF($B$4:$C$4, R$2)>0, VLOOKUP($J4,'Gear Values'!$A$2:$E$13, IF(COUNTBLANK('Attributes & Prefixes'!$B$4:$C$4)>0, "2", "3"), 0), COUNTIF($D$4:$E$4, R$2)>0, VLOOKUP($J4,'Gear Values'!$A$2:$E$13, IF(COUNTBLANK('Attributes & Prefixes'!$B$4:$C$4)>0, "4", "5"), 0)), "")} | S4: {=IF(COUNTIF($B$4:$E$4, S$2)>0, _xlfn.IFS(COUNTIF($B$4:$C$4, S$2)>0, VLOOKUP($J4,'Gear Values'!$A$2:$E$13, IF(COUNTBLANK('Attributes & Prefixes'!$B$4:$C$4)>0, "2", "3"), 0), COUNTIF($D$4:$E$4, S$2)>0, VLOOKUP($J4,'Gear Values'!$A$2:$E$13, IF(COUNTBLANK('Attributes & Prefixes'!$B$4:$C$4)>0, "4", "5"), 0)), "")} -> 171
